# 七、题目集合

## 7-1、Promise 相关

### 7-1-1、基本

```js
const promise1 = new Promise((resolve, reject) => {
  console.log('promise1')
})
console.log('1', promise1);
// 'promise1'
// '1' Promise{<pending>}
// 1、new Promise 执行、执行同步代码 1，此时 promise1 没有被 resolve 或者 reject，因此状态还是 pending


// Ex2
const promise = new Promise((resolve, reject) => {
  console.log(1);
  resolve('success')
  console.log(2);
});
promise.then(() => {
  console.log(3);
});
console.log(4);
// 1 2 4 3
// 1、new Promise 执行
// 2、resolve('success')， 更改 promise 状态为 resolved 并将值保存
// 3、执行同步代码2
// 4、跳出 promise，往下执行，碰到 promise.then 微任务，将其加入微任务队列
// 5、执行同步代码 4
// 6、本轮宏任务全部执行完毕，检查微任务队列，发现 promise.then 这个微任务且状态为 resolved，执行它。



// Ex3
const promise = new Promise((resolve, reject) => {
  console.log(1);
  console.log(2);
});
promise.then(() => {
  console.log(3);
});
console.log(4);
// 1 2 4
// 1、在 promise 中并没有 resolve 或 reject 因此 promise.then 并不会执行，它只有在被改变了状态之后才会执行



// Ex4
const promise1 = new Promise((resolve, reject) => {
  console.log('promise1')
  resolve('resolve1')
})
const promise2 = promise1.then(res => {
  console.log(res)
})
console.log('1', promise1);
console.log('2', promise2);
// 'promise1'
// '1' Promise{<resolved>: 'resolve1'}
// '2' Promise{<pending>}
// 'resolve1'

// 1、new Promise，执行
// 2、resolve 状态改变为 resolved, 并将结果保存下来
// 3、promise1.then 微任务，将它放入微任务队列
// 4、promise2 是一个新的状态为 pending 的Promise
// 5、执行同步代码1，同时打印出 promise1 状态 resolved
// 6、执行同步代码2，同时打印出 promise2 状态 pending
// 7、宏任务执行完毕，查找微任务队列，发现 promise1.then 且状态为 resolved，执行它


// Ex5
const fn = () => (new Promise((resolve, reject) => {
  console.log(1);
  resolve('success')
}))
fn().then(res => {
  console.log(res)
})
console.log('start')
// 1
// 'start'
// 'success'


// Ex6
const fn = () =>
  new Promise((resolve, reject) => {
    console.log(1);
    resolve("success");
  });
console.log("start");
fn().then(res => {
  console.log(res);
});
// 'start'
// 1
// 'success'
```



### 7-1-2、基本 + setTimeout

```js
console.log('start')
setTimeout(() => {
  console.log('time')
})
Promise.resolve().then(() => {
  console.log('resolve')
})
console.log('end')
// 'start'
// 'end'
// 'resolve'
// 'time'

// 1、同步代码直接压入执行栈进行执行
// 2、setTimout 作为一个宏任务被放入下一个宏任务队列
// 3、Promise.then 作为一个微任务被放入微任务队列
// 4、本次宏任务执行完，检查微任务，发现 Promise.then，执行
// 5、进入下一个宏任务，发现 setTimeout，执行


// Ex2
const promise = new Promise((resolve, reject) => {
  console.log(1);
  setTimeout(() => {
    console.log("timerStart");
    resolve("success");
    console.log("timerEnd");
  }, 0);
  console.log(2);
});
promise.then((res) => {
  console.log(res);
});
console.log(4);
// 1 2 4 timeStart timerEnd success

// 1、new Promise，执行
// 2、定时器，存入下一个宏任务的延迟队列中等待执行
// 3、执行同步代码2
// 4、跳出 promise 函数，遇到 promise.then，但其状态还是为 pending，理解为先不执行
// 5、执行同步代码4
// 6、一轮循环过后，进入二次宏任务，发现延迟队列中有 setTimeout 定时器，执行它
// 7、resolve，将 promise 状态改为 resolved 且保存结果，并将之前的 promise.then 推入微任务队列(???这里才加入么???)
// 8、继续执行同步代码 timerEnd
// 9、宏任务全部执行完毕，查找微任务队列，发现 promise.then 微任务，执行它

// Ex3-1
setTimeout(() => {
  console.log('timer1');
  setTimeout(() => {
    console.log('timer3')
  }, 0)
}, 0)
setTimeout(() => {
  console.log('timer2')
}, 0)
console.log('start')
// start timer1 timer2 timer3

// Ex3-2
setTimeout(() => {
  console.log('timer1');
  Promise.resolve().then(() => {
    console.log('promise')
  })
}, 0)
setTimeout(() => {
  console.log('timer2')
}, 0)
console.log('start')
// start timer1 timer2 promise

// Ex3-3
Promise.resolve().then(() => {
  console.log('promise1');
  const timer2 = setTimeout(() => {
    console.log('timer2')
  }, 0)
});
const timer1 = setTimeout(() => {
  console.log('timer1')
  Promise.resolve().then(() => {
    console.log('promise2')
  })
}, 0)
console.log('start');
// start promise1 timer1 promise2 timer2



// Ex4
const promise1 = new Promise((resolve, reject) => {
  setTimeout(() => {
    resolve('success')
  }, 1000)
})
const promise2 = promise1.then(() => {
  throw new Error('error!!!')
})
console.log('promise1', promise1)
console.log('promise2', promise2)
setTimeout(() => {
  console.log('promise1', promise1)
  console.log('promise2', promise2)
}, 2000)
// 'promise1' Promise{<pending>}
// 'promise2' Promise{<pending>}
// test5.html:102 Uncaught (in promise) Error: error!!! at test.html:102
// 'promise1' Promise{<resolved>: "success"}
// 'promise2' Promise{<rejected>: Error: error!!!}



// Ex5 - 注意 resolve/reject 后才会执行 then
const promise1 = new Promise((resolve, reject) => {
  setTimeout(() => {
    resolve("success");
    console.log("timer1");
  }, 1000);
  console.log("promise1 ok");
});
const promise2 = promise1.then(() => {
  throw new Error("error!!!");
});
console.log("promise1", promise1);
console.log("promise2", promise2);
setTimeout(() => {
  console.log("timer2");
  console.log("promise1", promise1);
  console.log("promise2", promise2);
}, 2000);
// promise1 ok
// 'promise1' Promise{<pending>}
// 'promise2' Promise{<pending>}
// timer1
// test5.html:102 Uncaught (in promise) Error: error!!! at test.html:102
// timer2
// 'promise1' Promise{<resolved>: "success"}
// 'promise2' Promise{<rejected>: Error: error!!!}
```

### 7-1-3、基本+then/catch/finally

1. `Promise` 状态一经改变就不能再改变；
   1. `Promise` 的 `.then` 或 `.catch` 可被调用多次, 当若 `Promise `内部状态一经改变，且有一个值，则后续每次调用 `.then` 或 `.catch` 时都会直接拿到该值；
2. `.then` 和 `.catch` 都会返回一新 `Promise`
   1. `Promise`  中，返回任意一个非 `promise`  值都会被包裹成 `promise` 对象，比如 `return 2`  会被包装为 `return Promise.resolve(2)`；
   2. `.then` 或 `.catch` 中 `return` 一个 `error` 对象并不会抛出错误，故不会被后续的 `.catch` 捕获；
   3. `.then` 或 `.catch` 返回值不能是 promise 本身，否则会造成死循环；
   4. `.then` 或 `.catch` 参数期望是函数，传入非函数则会发生值透传；
3. `catch ` 不管被连接到哪里，都能捕获上层的错误；
4. `.then` 能接收两个参数，第一个是处理成功的函数，第二个是处理失败的函数，某些时候可认为 `catch` 是 `.then` 第二个参数的简便写法；
5. `.finally` 返回一个 `Promise`，在  `Promise` 结束时，无论结果为  `resolved` 还是  `rejected`(无论状态如何均为执行)，都会执行里面的回调函数；也正因如此，finally 回调函数不接受任何的参数，即在 `.finally()` 函数中无法知道 `Promise` 最终状态；其最终返回的默认会是一个<u>上一次的 Promise 对象值</u>，不过如果抛出的是一个异常则返回异常的`Promise`对象；
6. `.finally` 报错方式有二且各自归属不同方法，`return new Error` 归属 then，throw new Error 归属 catch，两者同时存在时，后者覆盖前者;
7. `.finally` 行为与 `.then` 一致，只是执行行为存在不同 (本质上是 then 方法的特例)；

```js
Promise.prototype.finally = function (callback) {
  let P = this.constructor
  return this.then(
    value  => P.resolve(callback()).then(() => value),
    reason => P.resolve(callback()).then(() => { throw reason })
  )
}
```

```js
const promise = new Promise((resolve, reject) => {
  resolve("success1");
  reject("error");
  resolve("success2");
});
promise
.then(res => {
	console.log("then: ", res);
}).catch(err => {
	console.log("catch: ", err);
})
// "then: success1"


// Ex2 - catch() 也会返回一个 Promise，且由于这个 Promise 没有返回值，所以打印出来的是 undefined
const promise = new Promise((resolve, reject) => {
  reject("error");
  resolve("success2");
});
promise.then(res => {
  console.log("then1: ", res);
}).then(res => {
  console.log("then2: ", res);
}).catch(err => {
  console.log("catch: ", err);
}).then(res => {
  console.log("then3: ", res);
})
// "catch: " "error"
// "then3: " undefined



// Ex3 - return 2 会被包装成 resolve(2)
Promise.resolve(1).then(res => {
  console.log(res);
  return 2;
})
  .catch(err => {
  return 3;
})
  .then(res => {
  console.log(res);
});
// 1 2

// Ex3-1
Promise.reject(1)
  .then(res => {
  console.log(res);
  return 2;
})
  .catch(err => {
  console.log(err);
  return 3
})
  .then(res => {
  console.log(res);
});
// 1 3



// Ex4 - .then 或者 .catch 可以被调用多次，但 Promise 构造函数只执行一次
const promise = new Promise((resolve, reject) => {
  setTimeout(() => {
    console.log('timer')
    resolve('success')
  }, 1000)
})
const start = Date.now();
promise.then(res => {
  console.log(res, Date.now() - start)
})
promise.then(res => {
  console.log(res, Date.now() - start)
})
// 'timer'
// success 1001
// success 100x/1001 - 前提 - 足够快




// Ex5 - 非 promise 的值都会被包裹成 promise 对象
// 因此 return new Error('error!!!') 也被包裹成了 return Promise.resolve(new Error('error!!!'))
Promise.resolve().then(() => {
  return new Error('error!!!')
}).then(res => {
  console.log("then: ", res)
}).catch(err => {
  console.log("catch: ", err)
})
// "then: " "Error: error!!!"
// 注意：若想抛出错误请:
// return Promise.reject(new Error('error!!!'));
// or
// throw new Error('error!!!')



// Ex7 - .then 或 .catch 返回的值不能是 promise 本身，否则会造成死循环
const promise = Promise.resolve().then(() => {
  return promise;
})
promise.catch(console.err)
// Uncaught (in promise) TypeError: Chaining cycle detected for promise #<Promise>



// Ex8 - .then 或者 .catch 的参数期望是函数，传入非函数则会发生值透传
// 一个是数字类型，一个是对象类型，因此发生了透传，将resolve(1) 的值直接传到最后一个then里
Promise.resolve(1)
  .then(2)
  .then(Promise.resolve(3))
  .then(console.log)
// 1



// Ex9
Promise.reject('err!!!')
  .then((res) => {
    console.log('success', res)
  }, (err) => {
    console.log('error', err)
  }).catch(err => {
    console.log('catch', err)
  })
// 'error' 'error!!!' 
// 如果去掉第二函数，则进入 catch: 'catch' 'error!!!'

// Ex9-1
Promise.resolve()
  .then(function success (res) {
    throw new Error('error!!!')
  }, function fail1 (err) {
    console.log('fail1', err)
  }).catch(function fail2 (err) {
    console.log('fail2', err)
  })
// fail2 Error: error!!!    at success (<anonymous>:3:11)




// Ex10
Promise.resolve('1')
  .then(res => {
    console.log(res)
  })
  .finally(() => {
    console.log('finally')
  })
Promise.resolve('2')
  .finally(() => {
    console.log('finally2')
  	return '我是finally2返回的值'
  })
  .then(res => {
    console.log('finally2后面的then函数', res)
  })



// Ex11 - return 的报错方式会被 then 捕获
Promise.resolve('1')
  .finally(() => {
    console.log('finally2')
    return new Error('finally return error')
  })
  .then(res => {
    console.log('then catch: ', res)
  })
  .catch(err => {
    console.log('catch catch: ', err)
  })
// finally2
// then catch 1

// Ex11 - 1 - throw 报错方式会被 catch 捕获
Promise.resolve('1')
  .finally(() => {
    console.log('finally1')
    throw new Error('finally throw error')
  })
  .then(res => {
    console.log('then catch: ', res)
  })
  .catch(err => {
    console.log('catch catch: ', err)
  })
// finally1
// catch catch Error finally throw error


// Ex11 - 2 - 两种报错方式同在则还是会被 catch 捕获
Promise.resolve('1')
  .finally(() => {
    console.log('finally1')
    throw new Error('finally throw error')
  })
  .finally(() => {
    console.log('finally2')
    return new Error('finally return error')
  })
  .then(res => {
    console.log('then catch: ', res)
  })
  .catch(err => {
    console.log('catch catch: ', err)
  })
// finally1
// finally2
// catch catch Error finally throw error

// Ex11 - 2 - 两种报错方式同在则还是会被 catch 捕获，不管顺序
Promise.resolve('1')
  .finally(() => {
    console.log('finally2')
    return new Error('finally return error')
  })
  .finally(() => {
    console.log('finally1')
    throw new Error('finally throw error')
  })
  .then(res => {
    console.log('then catch: ', res)
  })
  .catch(err => {
    console.log('catch catch: ', err)
  })
// finally2
// finally1
// catch catch Error finally throw error



// Ex12
// 1、最终返回的默认会是一个上一次的 Promise 对象值，不过如果抛出的是一个异常则返回异常的 Promise 对象
// 2、.finally() 方法不管 Promise 对象最后的状态如何都会执行
// 3、.finally() 方法的回调函数不接受任何的参数，也即在 .finally() 函数中无法得知 Promise 最终状态
// 4、关于 finally2 为何先执行，看 Ex13 系列, 实际上是关于微任务的添加顺序，
Promise.resolve('1')
  .then(res => {
    console.log(res)
  })
  .finally(() => {
    console.log('finally')
  })
Promise.resolve('2')
  .finally(() => {
    console.log('finally2')
  	return 'finally2 return'
  })
  .then(res => {
    console.log('finally2 then', res)
  }
// '1'
// 'finally2'
// 'finally'
// 'finally2 then' '2'
        
        
// Ex13 - 1
function promise1 () {
  return new Promise((resolve) => {
    resolve('p1')
  })
}
function promise2 () {
  return new Promise((resolve, reject) => {
   	resolve('p2')
  })
}
promise1()
  .then(res => console.log(res + ' p1t1'))
  .then(res => console.log(res + ' p1t2'))
  .catch(err => console.log(err + ' p1e1'))
  .finally(() => console.log('finally1'))
  .then(res => console.log(res + ' p1t3'))
promise2()
  .then(res => console.log(res + ' p2t1'))
  .then(res => console.log(res + ' p2t2'))
  .catch(err => console.log(err + ' p2e1'))
  .finally(() => console.log('finally2'))
  .then(res => console.log(res + ' p2t3'))
// p1 p1t1
// p2 p2t1
// undefined p1t2
// undefined p2t2
// finally1
// finally2
// undefined p1t3
// undefined p2t3
```



### 7-1-4、基本+all/race

- `Promise.all()`的作用是接收一组异步任务，然后并行执行异步任务，并且在所有异步操作执行完后才执行回调；
- `.race()` 作用也是接收一组异步任务，然后并行执行异步任务，只保留取第一个执行完成的异步操作的结果，其他的方法仍在执行，不过执行结果会被抛弃；
- `Promise.all().then()` 结果中数组的顺序和 `Promise.all()` 接收到的数组顺序一致；

```js
// all
// 立即执行
const p1 = new Promise(r => console.log('立即打印'))

// 函数包裹控制执行
var runP1 = () => new Promise(r => console.log('立即打印')
runP1()

// all 并发执行，全部执行完毕才返回
var runAsync = (x) => new Promise(r => setTimeout(() => r(x, console.log(x)), 1000 * x));
Promise.all([runAsync(1), runAsync(2), runAsync(3)]).then(res => console.log(res))

// all .catch 会捕获最先的那个异常 - 懵逼 - all/race 用法
var runReject = (x) => new Promise((res, rej) => setTimeout(() => rej(`Error: ${x}`, console.log(x)), 1000 * x));
Promise.all([runAsync(1), runReject(4), runAsync(3), runReject(2)])
  .then(res => console.log(res))
  .catch(err => console.log(err))
// 1 3 2s后输出: 2Error: 2  4s后输出: 4





// race
Promise.race([runAsync(1), runAsync(2), runAsync(3)])
  .then(res => console.log('result: ', res))
  .catch(err => console.log(err))
// 1 
// 'result: ' 
// 1 
// 2 
// 3
Promise.race([runReject(0), runAsync(1), runAsync(2), runAsync(3)])
  .then(res => console.log("result: ", res))
  .catch(err => console.log(err));
// 0 'Error: 0'
// 1
// 2
// 3
```



## 7-2、Async/Await 相关

```js
// Ex1 - 可理解为 await 后面的内容就相当于放到了 Promise.then 中
async function async1() {
  console.log("async1 start");
  await async2();
  console.log("async1 end");
}
async function async2() {
  console.log("async2");
}
async1();
console.log('start')
// 'async1 start'
// 'async2'
// 'start'
// 'async1 end'


// Ex2
async function async1() {
  console.log("async1 start");
  new Promise(resolve => {
    console.log('promise')
  })
  console.log("async1 end");
}
async1();
console.log("start")
// 'async start'
// 'promise'
// 'async1 end'
// 'start'


// Ex3
async function async1() {
  console.log("async1 start");
  await async2();
  console.log("async1 end");
}
async function async2() {
  setTimeout(() => {
    console.log('timer')
  }, 0)
  console.log("async2");
}
async1();
console.log("start")
// 'async1 start'
// 'async2'
// 'start'
// 'async1 end'
// 'timer'




// Ex4
async function async1() {
  console.log("async1 start");
  await async2();
  console.log("async1 end");
  setTimeout(() => {
    console.log('timer1')
  }, 0)
}
async function async2() {
  setTimeout(() => {
    console.log('timer2')
  }, 0)
  console.log("async2");
}
async1();
setTimeout(() => {
  console.log('timer3')
}, 0)
console.log("start")
// 'async1 start'
// 'async2'
// 'start'
// 'async1 end'
// 'timer2'
// 'timer3'
// 'timer1'



// Ex5 - async 中的 await 命令是一个 Promise 对象，返回该对象的结果,
// 但若非 Promise 对象，就会直接返回对应的值，相当于 Promise.resolve()
async function fn () {
  // return await 1234
  // 等同于
  return 123
}
fn().then(res => console.log(res))



// Ex6 - async1 中 await 后面的 Promise 是没有返回值的，也就是它的状态始终是 pending 状态，因此相当于一直在 await
async function async1 () {
  console.log('async1 start');
  await new Promise(resolve => {
    console.log('promise1')
  })
  console.log('async1 success');
  return 'async1 end'
}
console.log('srcipt start')
async1().then(res => console.log(res))
console.log('srcipt end')
// 'script start'
// 'async1 start'
// 'promise1'
// 'script end'

// Ex6-1 - 有了返回值，await 后面的内容将会被执行
async function async1 () {
  console.log('async1 start');
  await new Promise(resolve => {
    console.log('promise1')
    resolve('promise1 resolve')
  }).then(res => console.log(res))
  console.log('async1 success');
  return 'async1 end'
}
console.log('srcipt start')
async1().then(res => console.log(res))
console.log('srcipt end')
// 'script start'
// 'async1 start'
// 'promise1'
// 'script end'
// 'promise1 resolve'
// 'async1 success'
// 'async1 end'



// Ex7
async function async1 () {
  console.log('async1 start');
  await new Promise(resolve => {
    console.log('promise1')
    resolve('promise resolve')
  })
  console.log('async1 success');
  return 'async1 end'
}
console.log('srcipt start')
async1().then(res => {
  console.log(res)
})
new Promise(resolve => {
  console.log('promise2')
  setTimeout(() => {
    console.log('timer')
  })
})
// 'script start'
// 'async1 start'
// 'promise1'
// 'promise2'
// 'async1 success'
// 'sync1 end'
// 'timer'



// EX8
async function async1() {
  console.log("async1 start");
  await async2();
  console.log("async1 end");
}
async function async2() {
  console.log("async2");
}
console.log("script start");
setTimeout(function() {
  console.log("setTimeout");
}, 0);
async1();
new Promise(function(resolve) {
  console.log("promise1");
  resolve();
}).then(function() {
  console.log("promise2");
});
console.log('script end')
// ss async1-start async2 promise1 se async-end promise2 se




// Ex9
async function testSometing() {
  console.log("执行testSometing");
  return "testSometing";
}

async function testAsync() {
  console.log("执行testAsync");
  return Promise.resolve("hello async");
}

async function test() {
  console.log("test start...");
  const v1 = await testSometing();
  console.log(v1);
  const v2 = await testAsync();
  console.log(v2);
  console.log(v1, v2);
}

test();

var promise = new Promise(resolve => {
  console.log("promise start...");
  resolve("promise");
});
promise.then(val => console.log(val));

console.log("test end...");
// 'test start...'
// '执行testSometing'
// 'promise start...'
// 'test end...'
// 'testSometing'
// '执行testAsync'
// 'promise'
// 'hello async'
// 'testSometing' 'hello async'





// Ex10 - 若在 async 函数中抛出了错误，则终止错误结果，不会继续向下执行
async function async1 () {
  await async2();
  console.log('async1');
  return 'async1 success'
}
async function async2 () {
  return new Promise((resolve, reject) => {
    console.log('async2')
    reject('error')
  })
}
async1().then(res => console.log(res))
// 'async2'
// Uncaught (in promise) error


// Ex10 - 1 - 改为 throw new Error 也是一样
async function async1 () {
  console.log('async1');
  throw new Error('error!!!')
  return 'async1 success'
}
async1().then(res => console.log(res))
// 'async1'
// Uncaught (in promise) Error: error!!!



// Ex11 - 针对上述问题，可用 try-catch 不影响后续执行
async function async1 () {
  try {
    await Promise.reject('error!!!')
  } catch(e) {
    console.log(e)
  }
  console.log('async1');
  return Promise.resolve('async1 success')
}
async1().then(res => console.log(res))
console.log('script start')
// 'script start'
// 'error!!!'
// 'async1'
// 'async1 success'

// 或直接在 Promise.reject 后面跟着一个 catch() 方法
async function async1 () {
  // try {
  //   await Promise.reject('error!!!')
  // } catch(e) {
  //   console.log(e)
  // }
  await Promise.reject('error!!!')
    .catch(e => console.log(e))
  console.log('async1');
  return Promise.resolve('async1 success')
}
async1().then(res => console.log(res))
console.log('script start')
// 'script start'
// 'error!!!'
// 'async1'
// 'async1 success'
```



## 7-X、综合题

```js
// Ex1
const first = () => (new Promise((resolve, reject) => {
    console.log(3);
    let p = new Promise((resolve, reject) => {
        console.log(7);
        setTimeout(() => {
            console.log(5);
            resolve(6);
            console.log(p)
        }, 0)
        resolve(1);
    });
    resolve(2);
    p.then((arg) => {
        console.log(arg);
    });
}));
first().then((arg) => {
    console.log(arg);
});
console.log(4);
// 3 7 4 1 2 5 Promise{<resolved>: 1}



// Ex2
// async 函数中 await 的 new Promise 要是没有返回值的话则不执行后面的内容
// .then 函数中的参数期待的是函数，如果不是函数的话会发生透传
// 注意定时器的延迟时间
const async1 = async () => {
  console.log('async1');
  setTimeout(() => {
    console.log('timer1')
  }, 2000)
  await new Promise(resolve => {
    console.log('promise1')
  })
  console.log('async1 end')
  return 'async1 success'
} 
console.log('script start');
async1().then(res => console.log(res));
console.log('script end');
Promise.resolve(1)
  .then(2)
  .then(Promise.resolve(3))
  .catch(4)
  .then(res => console.log(res))
setTimeout(() => {
  console.log('timer2')
}, 1000)
// 'script start'
// 'async1'
// 'promise1'
// 'script end'
// 1
// 'timer2'
// 'timer1'




// Ex3
// Promise 状态一旦改变就无法改变
// finally 不管 Promise的状态是 resolved 还是 rejected 都会执行，且它的回调函数是接收不到 Promise 结果，所以 finally() 中的 res 是一个迷惑项
// 最后一个定时器打印出的 p1 其实是 .finally 返回值，.finally 返回值如果在没有抛出错误的情况下默认会是上一个 Promise 返回值, 而这道题中 .finally 上一个 Promise 是 .then()，但这个 .then() 并无返回值，故 p1 打印出来的 Promise 值是 undefined，若在定时器的下面加上一个 return 1，则值就会变成1
const p1 = new Promise((resolve) => {
  setTimeout(() => {
    resolve('resolve3');
    console.log('timer1')
  }, 0)
  resolve('resovle1');
  resolve('resolve2');
}).then(res => {
  console.log(res)
  setTimeout(() => {
    console.log(p1)
  }, 1000)
}).finally(res => {
  console.log('finally', res)
})
// 'resolve1'
// 'finally' undefined
// 'timer1'
// Promise{<resolved>: undefined}
```





## 7-Y、面试相关题

### 7-Y-1、红绿灯闪烁

红灯3秒亮一次，黄灯2秒亮一次，绿灯1秒亮一次；如何让三个灯不断交替重复亮灯

```js
function red() {
  console.log("red");
}
function green() {
  console.log("green");
}
function yellow() {
  console.log("yellow");
}
const light = function (timer, cb) {
  return new Promise(resolve => {
    setTimeout(() => {
      cb()
      resolve()
    }, timer)
  })
}
const step = function () {
  Promise.resolve().then(() => {
    return light(3000, red)
  }).then(() => {
    return light(2000, green)
  }).then(() => {
    return light(1000, yellow)
  }).then(() => {
    return step()
  })
}

step();
```



### 7-Y-2、实现 mergePromise

实现 mergePromise 函数，把传进去的数组按顺序先后执行，并且把返回的数据先后放到数组 data 中

```js
// 将零碎合整，化为链式调用
const time = (timer) => {
  return new Promise(resolve => {
    setTimeout(() => {
      resolve()
    }, timer)
  })
}
const ajax1 = () => time(2000).then(() => {
  console.log(1);
  return 1
})
const ajax2 = () => time(1000).then(() => {
  console.log(2);
  return 2
})
const ajax3 = () => time(1000).then(() => {
  console.log(3);
  return 3
})

function mergePromise (ajaxArray) {
  // 存放每个ajax的结果
  const data = [];
  let promise = Promise.resolve();
  ajaxArray.forEach(ajax => {
  	// 第一次的then为了用来调用ajax
  	// 第二次的then是为了获取ajax的结果
    promise = promise.then(ajax).then(res => {
      data.push(res);
      return data; // 把每次的结果返回
    })
  })
  // 最后得到的promise它的值就是data
  return promise;
}

mergePromise([ajax1, ajax2, ajax3]).then(data => {
  console.log("done");
  console.log(data); // data 为 [1, 2, 3]
});

// 要求分别输出
// 1
// 2
// 3
// done
// [1, 2, 3]
```



